bash: cd: too many arguments
bash: cd: too many arguments
2025-10-17 15:57:19,256 | INFO | src.extract | Requesting source API: https://jsonplaceholder.typicode.com/posts
2025-10-17 15:57:19,993 | INFO | src.extract | Fetched 100 records
2025-10-17 15:57:20,159 | INFO | src.transform | dim_user=10, dim_category=1, dim_sla=1, fact_ticket=100
2025-10-17 15:57:21,192 | INFO | src.load | Upserted 10 rows into dw.dim_user
2025-10-17 15:57:21,591 | INFO | src.load | Upserted 1 rows into dw.dim_category
2025-10-17 15:57:21,770 | INFO | src.load | Upserted 1 rows into dw.dim_sla
2025-10-17 15:57:22,092 | INFO | src.load | Upserted 100 rows into dw.fact_ticket
Loading .env from: /mnt/c/Users/ACER/Documents/service-desk-etl/.env
BASE = https://jsonplaceholder.typicode.com
ENDPOINT = /posts
2025-10-17 15:59:05,026 | INFO | src.extract | Requesting source API: https://jsonplaceholder.typicode.com/posts
2025-10-17 15:59:05,491 | INFO | src.extract | Fetched 100 records
2025-10-17 15:59:05,579 | INFO | src.transform | dim_user=10, dim_category=1, dim_sla=1, fact_ticket=100
2025-10-17 15:59:06,261 | INFO | src.load | Upserted 10 rows into dw.dim_user
2025-10-17 15:59:06,475 | INFO | src.load | Upserted 1 rows into dw.dim_category
2025-10-17 15:59:06,717 | INFO | src.load | Upserted 1 rows into dw.dim_sla
2025-10-17 15:59:07,288 | INFO | src.load | Upserted 100 rows into dw.fact_ticket
Loading .env from: /mnt/c/Users/ACER/Documents/service-desk-etl/.env
BASE = https://jsonplaceholder.typicode.com
ENDPOINT = /posts
2025-10-20 09:00:08,460 | INFO | src.extract | Requesting source API: https://jsonplaceholder.typicode.com/posts
2025-10-20 09:00:09,299 | INFO | src.extract | Fetched 100 records
2025-10-20 09:00:09,376 | INFO | src.transform | dim_user=10, dim_category=1, dim_sla=1, fact_ticket=100
2025-10-20 09:00:10,240 | INFO | src.load | Upserted 10 rows into dw.dim_user
2025-10-20 09:00:10,386 | INFO | src.load | Upserted 1 rows into dw.dim_category
2025-10-20 09:00:10,538 | INFO | src.load | Upserted 1 rows into dw.dim_sla
2025-10-20 09:00:10,765 | INFO | src.load | Upserted 100 rows into dw.fact_ticket
Loading .env from: /mnt/c/Users/ACER/Documents/service-desk-etl/.env
BASE = https://jsonplaceholder.typicode.com
ENDPOINT = /posts
2025-10-20 15:00:08,431 | INFO | src.extract | Requesting source API: https://jsonplaceholder.typicode.com/posts
2025-10-20 15:00:09,447 | INFO | src.extract | Fetched 100 records
2025-10-20 15:00:09,508 | INFO | src.transform | dim_user=10, dim_category=1, dim_sla=1, fact_ticket=100
2025-10-20 15:00:09,859 | INFO | src.load | Upserted 10 rows into dw.dim_user
2025-10-20 15:00:09,959 | INFO | src.load | Upserted 1 rows into dw.dim_category
2025-10-20 15:00:10,063 | INFO | src.load | Upserted 1 rows into dw.dim_sla
2025-10-20 15:00:10,212 | INFO | src.load | Upserted 100 rows into dw.fact_ticket
Loading .env from: /mnt/c/Users/ACER/Documents/service-desk-etl/.env
BASE = https://jsonplaceholder.typicode.com
ENDPOINT = /posts
2025-10-21 09:00:06,266 | INFO | src.extract | Requesting source API: https://jsonplaceholder.typicode.com/posts
2025-10-21 09:00:07,502 | INFO | src.extract | Fetched 100 records
2025-10-21 09:00:07,533 | INFO | src.transform | dim_user=10, dim_category=1, dim_sla=1, fact_ticket=100
2025-10-21 09:00:07,742 | INFO | src.load | Upserted 10 rows into dw.dim_user
2025-10-21 09:00:07,813 | INFO | src.load | Upserted 1 rows into dw.dim_category
2025-10-21 09:00:07,898 | INFO | src.load | Upserted 1 rows into dw.dim_sla
2025-10-21 09:00:08,036 | INFO | src.load | Upserted 100 rows into dw.fact_ticket
Loading .env from: /mnt/c/Users/ACER/Documents/service-desk-etl/.env
BASE = https://jsonplaceholder.typicode.com
ENDPOINT = /posts
2025-10-21 15:00:06,529 | INFO | __main__ | ===== Starting ETL Run ([AUTO-CRON]) =====
2025-10-21 15:00:06,716 | INFO | src.extract | Requesting source API: https://jsonplaceholder.typicode.com/posts
2025-10-21 15:00:07,980 | INFO | src.extract | Fetched 100 records
2025-10-21 15:00:07,985 | INFO | __main__ | Fetched 100 raw records
2025-10-21 15:00:08,030 | INFO | src.transform | dim_user=10, dim_category=1, dim_sla=1, fact_ticket=100
2025-10-21 15:00:08,045 | INFO | __main__ | DQ Checks: None
2025-10-21 15:00:08,260 | INFO | src.load | Upserted 10 rows into dw.dim_user
2025-10-21 15:00:08,349 | INFO | src.load | Upserted 1 rows into dw.dim_category
2025-10-21 15:00:08,421 | INFO | src.load | Upserted 1 rows into dw.dim_sla
2025-10-21 15:00:08,521 | INFO | src.load | Upserted 100 rows into dw.fact_ticket
2025-10-21 15:00:08,570 | INFO | __main__ | ETL run complete with status=SUCCESS
Loading .env from: /mnt/c/Users/ACER/Documents/service-desk-etl/.env
BASE = https://jsonplaceholder.typicode.com
ENDPOINT = /posts
2025-10-22 09:00:15,907 | INFO | __main__ | ===== Starting ETL Run ([AUTO-CRON]) =====
2025-10-22 09:00:16,772 | INFO | src.extract | Requesting source API: https://jsonplaceholder.typicode.com/posts
2025-10-22 09:00:18,552 | INFO | src.extract | Fetched 100 records
2025-10-22 09:00:18,673 | INFO | __main__ | Fetched 100 raw records
2025-10-22 09:00:18,934 | INFO | src.transform | dim_user=10, dim_category=1, dim_sla=1, fact_ticket=100
2025-10-22 09:00:19,008 | INFO | __main__ | DQ Checks: None
2025-10-22 09:00:19,554 | ERROR | __main__ | ETL Failed
Traceback (most recent call last):
  File "/home/root123/.local/lib/python3.12/site-packages/sqlalchemy/engine/base.py", line 143, in __init__
    self._dbapi_connection = engine.raw_connection()
                             ^^^^^^^^^^^^^^^^^^^^^^^
  File "/home/root123/.local/lib/python3.12/site-packages/sqlalchemy/engine/base.py", line 3301, in raw_connection
    return self.pool.connect()
           ^^^^^^^^^^^^^^^^^^^
  File "/home/root123/.local/lib/python3.12/site-packages/sqlalchemy/pool/base.py", line 447, in connect
    return _ConnectionFairy._checkout(self)
           ^^^^^^^^^^^^^^^^^^^^^^^^^^^^^^^^
  File "/home/root123/.local/lib/python3.12/site-packages/sqlalchemy/pool/base.py", line 1264, in _checkout
    fairy = _ConnectionRecord.checkout(pool)
            ^^^^^^^^^^^^^^^^^^^^^^^^^^^^^^^^
  File "/home/root123/.local/lib/python3.12/site-packages/sqlalchemy/pool/base.py", line 711, in checkout
    rec = pool._do_get()
          ^^^^^^^^^^^^^^
  File "/home/root123/.local/lib/python3.12/site-packages/sqlalchemy/pool/impl.py", line 177, in _do_get
    with util.safe_reraise():
  File "/home/root123/.local/lib/python3.12/site-packages/sqlalchemy/util/langhelpers.py", line 224, in __exit__
    raise exc_value.with_traceback(exc_tb)
  File "/home/root123/.local/lib/python3.12/site-packages/sqlalchemy/pool/impl.py", line 175, in _do_get
    return self._create_connection()
           ^^^^^^^^^^^^^^^^^^^^^^^^^
  File "/home/root123/.local/lib/python3.12/site-packages/sqlalchemy/pool/base.py", line 388, in _create_connection
    return _ConnectionRecord(self)
           ^^^^^^^^^^^^^^^^^^^^^^^
  File "/home/root123/.local/lib/python3.12/site-packages/sqlalchemy/pool/base.py", line 673, in __init__
    self.__connect()
  File "/home/root123/.local/lib/python3.12/site-packages/sqlalchemy/pool/base.py", line 899, in __connect
    with util.safe_reraise():
  File "/home/root123/.local/lib/python3.12/site-packages/sqlalchemy/util/langhelpers.py", line 224, in __exit__
    raise exc_value.with_traceback(exc_tb)
  File "/home/root123/.local/lib/python3.12/site-packages/sqlalchemy/pool/base.py", line 895, in __connect
    self.dbapi_connection = connection = pool._invoke_creator(self)
                                         ^^^^^^^^^^^^^^^^^^^^^^^^^^
  File "/home/root123/.local/lib/python3.12/site-packages/sqlalchemy/engine/create.py", line 661, in connect
    return dialect.connect(*cargs, **cparams)
           ^^^^^^^^^^^^^^^^^^^^^^^^^^^^^^^^^^
  File "/home/root123/.local/lib/python3.12/site-packages/sqlalchemy/engine/default.py", line 629, in connect
    return self.loaded_dbapi.connect(*cargs, **cparams)  # type: ignore[no-any-return]  # NOQA: E501
           ^^^^^^^^^^^^^^^^^^^^^^^^^^^^^^^^^^^^^^^^^^^^
  File "/home/root123/.local/lib/python3.12/site-packages/psycopg2/__init__.py", line 122, in connect
    conn = _connect(dsn, connection_factory=connection_factory, **kwasync)
           ^^^^^^^^^^^^^^^^^^^^^^^^^^^^^^^^^^^^^^^^^^^^^^^^^^^^^^^^^^^^^^^
psycopg2.OperationalError: connection to server at "localhost" (127.0.0.1), port 5432 failed: Connection refused
	Is the server running on that host and accepting TCP/IP connections?


The above exception was the direct cause of the following exception:

Traceback (most recent call last):
  File "/mnt/c/Users/ACER/Documents/service-desk-etl/src/main.py", line 44, in run
    upsert_frame(tables["dim_user"], "dim_user", ["user_id"])
  File "/mnt/c/Users/ACER/Documents/service-desk-etl/src/load.py", line 14, in upsert_frame
    with engine.begin() as conn:
  File "/usr/lib/python3.12/contextlib.py", line 137, in __enter__
    return next(self.gen)
           ^^^^^^^^^^^^^^
  File "/home/root123/.local/lib/python3.12/site-packages/sqlalchemy/engine/base.py", line 3241, in begin
    with self.connect() as conn:
         ^^^^^^^^^^^^^^
  File "/home/root123/.local/lib/python3.12/site-packages/sqlalchemy/engine/base.py", line 3277, in connect
    return self._connection_cls(self)
           ^^^^^^^^^^^^^^^^^^^^^^^^^^
  File "/home/root123/.local/lib/python3.12/site-packages/sqlalchemy/engine/base.py", line 145, in __init__
    Connection._handle_dbapi_exception_noconnection(
  File "/home/root123/.local/lib/python3.12/site-packages/sqlalchemy/engine/base.py", line 2440, in _handle_dbapi_exception_noconnection
    raise sqlalchemy_exception.with_traceback(exc_info[2]) from e
  File "/home/root123/.local/lib/python3.12/site-packages/sqlalchemy/engine/base.py", line 143, in __init__
    self._dbapi_connection = engine.raw_connection()
                             ^^^^^^^^^^^^^^^^^^^^^^^
  File "/home/root123/.local/lib/python3.12/site-packages/sqlalchemy/engine/base.py", line 3301, in raw_connection
    return self.pool.connect()
           ^^^^^^^^^^^^^^^^^^^
  File "/home/root123/.local/lib/python3.12/site-packages/sqlalchemy/pool/base.py", line 447, in connect
    return _ConnectionFairy._checkout(self)
           ^^^^^^^^^^^^^^^^^^^^^^^^^^^^^^^^
  File "/home/root123/.local/lib/python3.12/site-packages/sqlalchemy/pool/base.py", line 1264, in _checkout
    fairy = _ConnectionRecord.checkout(pool)
            ^^^^^^^^^^^^^^^^^^^^^^^^^^^^^^^^
  File "/home/root123/.local/lib/python3.12/site-packages/sqlalchemy/pool/base.py", line 711, in checkout
    rec = pool._do_get()
          ^^^^^^^^^^^^^^
  File "/home/root123/.local/lib/python3.12/site-packages/sqlalchemy/pool/impl.py", line 177, in _do_get
    with util.safe_reraise():
  File "/home/root123/.local/lib/python3.12/site-packages/sqlalchemy/util/langhelpers.py", line 224, in __exit__
    raise exc_value.with_traceback(exc_tb)
  File "/home/root123/.local/lib/python3.12/site-packages/sqlalchemy/pool/impl.py", line 175, in _do_get
    return self._create_connection()
           ^^^^^^^^^^^^^^^^^^^^^^^^^
  File "/home/root123/.local/lib/python3.12/site-packages/sqlalchemy/pool/base.py", line 388, in _create_connection
    return _ConnectionRecord(self)
           ^^^^^^^^^^^^^^^^^^^^^^^
  File "/home/root123/.local/lib/python3.12/site-packages/sqlalchemy/pool/base.py", line 673, in __init__
    self.__connect()
  File "/home/root123/.local/lib/python3.12/site-packages/sqlalchemy/pool/base.py", line 899, in __connect
    with util.safe_reraise():
  File "/home/root123/.local/lib/python3.12/site-packages/sqlalchemy/util/langhelpers.py", line 224, in __exit__
    raise exc_value.with_traceback(exc_tb)
  File "/home/root123/.local/lib/python3.12/site-packages/sqlalchemy/pool/base.py", line 895, in __connect
    self.dbapi_connection = connection = pool._invoke_creator(self)
                                         ^^^^^^^^^^^^^^^^^^^^^^^^^^
  File "/home/root123/.local/lib/python3.12/site-packages/sqlalchemy/engine/create.py", line 661, in connect
    return dialect.connect(*cargs, **cparams)
           ^^^^^^^^^^^^^^^^^^^^^^^^^^^^^^^^^^
  File "/home/root123/.local/lib/python3.12/site-packages/sqlalchemy/engine/default.py", line 629, in connect
    return self.loaded_dbapi.connect(*cargs, **cparams)  # type: ignore[no-any-return]  # NOQA: E501
           ^^^^^^^^^^^^^^^^^^^^^^^^^^^^^^^^^^^^^^^^^^^^
  File "/home/root123/.local/lib/python3.12/site-packages/psycopg2/__init__.py", line 122, in connect
    conn = _connect(dsn, connection_factory=connection_factory, **kwasync)
           ^^^^^^^^^^^^^^^^^^^^^^^^^^^^^^^^^^^^^^^^^^^^^^^^^^^^^^^^^^^^^^^
sqlalchemy.exc.OperationalError: (psycopg2.OperationalError) connection to server at "localhost" (127.0.0.1), port 5432 failed: Connection refused
	Is the server running on that host and accepting TCP/IP connections?

(Background on this error at: https://sqlalche.me/e/20/e3q8)
Traceback (most recent call last):
  File "/home/root123/.local/lib/python3.12/site-packages/sqlalchemy/engine/base.py", line 143, in __init__
    self._dbapi_connection = engine.raw_connection()
                             ^^^^^^^^^^^^^^^^^^^^^^^
  File "/home/root123/.local/lib/python3.12/site-packages/sqlalchemy/engine/base.py", line 3301, in raw_connection
    return self.pool.connect()
           ^^^^^^^^^^^^^^^^^^^
  File "/home/root123/.local/lib/python3.12/site-packages/sqlalchemy/pool/base.py", line 447, in connect
    return _ConnectionFairy._checkout(self)
           ^^^^^^^^^^^^^^^^^^^^^^^^^^^^^^^^
  File "/home/root123/.local/lib/python3.12/site-packages/sqlalchemy/pool/base.py", line 1264, in _checkout
    fairy = _ConnectionRecord.checkout(pool)
            ^^^^^^^^^^^^^^^^^^^^^^^^^^^^^^^^
  File "/home/root123/.local/lib/python3.12/site-packages/sqlalchemy/pool/base.py", line 711, in checkout
    rec = pool._do_get()
          ^^^^^^^^^^^^^^
  File "/home/root123/.local/lib/python3.12/site-packages/sqlalchemy/pool/impl.py", line 177, in _do_get
    with util.safe_reraise():
  File "/home/root123/.local/lib/python3.12/site-packages/sqlalchemy/util/langhelpers.py", line 224, in __exit__
    raise exc_value.with_traceback(exc_tb)
  File "/home/root123/.local/lib/python3.12/site-packages/sqlalchemy/pool/impl.py", line 175, in _do_get
    return self._create_connection()
           ^^^^^^^^^^^^^^^^^^^^^^^^^
  File "/home/root123/.local/lib/python3.12/site-packages/sqlalchemy/pool/base.py", line 388, in _create_connection
    return _ConnectionRecord(self)
           ^^^^^^^^^^^^^^^^^^^^^^^
  File "/home/root123/.local/lib/python3.12/site-packages/sqlalchemy/pool/base.py", line 673, in __init__
    self.__connect()
  File "/home/root123/.local/lib/python3.12/site-packages/sqlalchemy/pool/base.py", line 899, in __connect
    with util.safe_reraise():
  File "/home/root123/.local/lib/python3.12/site-packages/sqlalchemy/util/langhelpers.py", line 224, in __exit__
    raise exc_value.with_traceback(exc_tb)
  File "/home/root123/.local/lib/python3.12/site-packages/sqlalchemy/pool/base.py", line 895, in __connect
    self.dbapi_connection = connection = pool._invoke_creator(self)
                                         ^^^^^^^^^^^^^^^^^^^^^^^^^^
  File "/home/root123/.local/lib/python3.12/site-packages/sqlalchemy/engine/create.py", line 661, in connect
    return dialect.connect(*cargs, **cparams)
           ^^^^^^^^^^^^^^^^^^^^^^^^^^^^^^^^^^
  File "/home/root123/.local/lib/python3.12/site-packages/sqlalchemy/engine/default.py", line 629, in connect
    return self.loaded_dbapi.connect(*cargs, **cparams)  # type: ignore[no-any-return]  # NOQA: E501
           ^^^^^^^^^^^^^^^^^^^^^^^^^^^^^^^^^^^^^^^^^^^^
  File "/home/root123/.local/lib/python3.12/site-packages/psycopg2/__init__.py", line 122, in connect
    conn = _connect(dsn, connection_factory=connection_factory, **kwasync)
           ^^^^^^^^^^^^^^^^^^^^^^^^^^^^^^^^^^^^^^^^^^^^^^^^^^^^^^^^^^^^^^^
psycopg2.OperationalError: connection to server at "localhost" (127.0.0.1), port 5432 failed: Connection refused
	Is the server running on that host and accepting TCP/IP connections?


The above exception was the direct cause of the following exception:

Traceback (most recent call last):
  File "<frozen runpy>", line 198, in _run_module_as_main
  File "<frozen runpy>", line 88, in _run_code
  File "/mnt/c/Users/ACER/Documents/service-desk-etl/src/main.py", line 70, in <module>
    run(tag)
  File "/mnt/c/Users/ACER/Documents/service-desk-etl/src/main.py", line 56, in run
    with engine.begin() as conn:
  File "/usr/lib/python3.12/contextlib.py", line 137, in __enter__
    return next(self.gen)
           ^^^^^^^^^^^^^^
  File "/home/root123/.local/lib/python3.12/site-packages/sqlalchemy/engine/base.py", line 3241, in begin
    with self.connect() as conn:
         ^^^^^^^^^^^^^^
  File "/home/root123/.local/lib/python3.12/site-packages/sqlalchemy/engine/base.py", line 3277, in connect
    return self._connection_cls(self)
           ^^^^^^^^^^^^^^^^^^^^^^^^^^
  File "/home/root123/.local/lib/python3.12/site-packages/sqlalchemy/engine/base.py", line 145, in __init__
    Connection._handle_dbapi_exception_noconnection(
  File "/home/root123/.local/lib/python3.12/site-packages/sqlalchemy/engine/base.py", line 2440, in _handle_dbapi_exception_noconnection
    raise sqlalchemy_exception.with_traceback(exc_info[2]) from e
  File "/home/root123/.local/lib/python3.12/site-packages/sqlalchemy/engine/base.py", line 143, in __init__
    self._dbapi_connection = engine.raw_connection()
                             ^^^^^^^^^^^^^^^^^^^^^^^
  File "/home/root123/.local/lib/python3.12/site-packages/sqlalchemy/engine/base.py", line 3301, in raw_connection
    return self.pool.connect()
           ^^^^^^^^^^^^^^^^^^^
  File "/home/root123/.local/lib/python3.12/site-packages/sqlalchemy/pool/base.py", line 447, in connect
    return _ConnectionFairy._checkout(self)
           ^^^^^^^^^^^^^^^^^^^^^^^^^^^^^^^^
  File "/home/root123/.local/lib/python3.12/site-packages/sqlalchemy/pool/base.py", line 1264, in _checkout
    fairy = _ConnectionRecord.checkout(pool)
            ^^^^^^^^^^^^^^^^^^^^^^^^^^^^^^^^
  File "/home/root123/.local/lib/python3.12/site-packages/sqlalchemy/pool/base.py", line 711, in checkout
    rec = pool._do_get()
          ^^^^^^^^^^^^^^
  File "/home/root123/.local/lib/python3.12/site-packages/sqlalchemy/pool/impl.py", line 177, in _do_get
    with util.safe_reraise():
  File "/home/root123/.local/lib/python3.12/site-packages/sqlalchemy/util/langhelpers.py", line 224, in __exit__
    raise exc_value.with_traceback(exc_tb)
  File "/home/root123/.local/lib/python3.12/site-packages/sqlalchemy/pool/impl.py", line 175, in _do_get
    return self._create_connection()
           ^^^^^^^^^^^^^^^^^^^^^^^^^
  File "/home/root123/.local/lib/python3.12/site-packages/sqlalchemy/pool/base.py", line 388, in _create_connection
    return _ConnectionRecord(self)
           ^^^^^^^^^^^^^^^^^^^^^^^
  File "/home/root123/.local/lib/python3.12/site-packages/sqlalchemy/pool/base.py", line 673, in __init__
    self.__connect()
  File "/home/root123/.local/lib/python3.12/site-packages/sqlalchemy/pool/base.py", line 899, in __connect
    with util.safe_reraise():
  File "/home/root123/.local/lib/python3.12/site-packages/sqlalchemy/util/langhelpers.py", line 224, in __exit__
    raise exc_value.with_traceback(exc_tb)
  File "/home/root123/.local/lib/python3.12/site-packages/sqlalchemy/pool/base.py", line 895, in __connect
    self.dbapi_connection = connection = pool._invoke_creator(self)
                                         ^^^^^^^^^^^^^^^^^^^^^^^^^^
  File "/home/root123/.local/lib/python3.12/site-packages/sqlalchemy/engine/create.py", line 661, in connect
    return dialect.connect(*cargs, **cparams)
           ^^^^^^^^^^^^^^^^^^^^^^^^^^^^^^^^^^
  File "/home/root123/.local/lib/python3.12/site-packages/sqlalchemy/engine/default.py", line 629, in connect
    return self.loaded_dbapi.connect(*cargs, **cparams)  # type: ignore[no-any-return]  # NOQA: E501
           ^^^^^^^^^^^^^^^^^^^^^^^^^^^^^^^^^^^^^^^^^^^^
  File "/home/root123/.local/lib/python3.12/site-packages/psycopg2/__init__.py", line 122, in connect
    conn = _connect(dsn, connection_factory=connection_factory, **kwasync)
           ^^^^^^^^^^^^^^^^^^^^^^^^^^^^^^^^^^^^^^^^^^^^^^^^^^^^^^^^^^^^^^^
sqlalchemy.exc.OperationalError: (psycopg2.OperationalError) connection to server at "localhost" (127.0.0.1), port 5432 failed: Connection refused
	Is the server running on that host and accepting TCP/IP connections?

(Background on this error at: https://sqlalche.me/e/20/e3q8)
 Loading .env from: /mnt/c/Users/ACER/Documents/service-desk-etl/.env
BASE = https://jsonplaceholder.typicode.com
ENDPOINT = /posts
Traceback (most recent call last):
  File "/usr/lib/python3.10/runpy.py", line 196, in _run_module_as_main
    return _run_code(code, main_globals, None,
  File "/usr/lib/python3.10/runpy.py", line 86, in _run_code
    exec(code, run_globals)
  File "/mnt/c/Users/ACER/Documents/service-desk-etl/src/main.py", line 1, in <module>
    from .extract import fetch_source_data
  File "/mnt/c/Users/ACER/Documents/service-desk-etl/src/extract.py", line 2, in <module>
    from tenacity import retry, stop_after_attempt, wait_exponential
ModuleNotFoundError: No module named 'tenacity'
Traceback (most recent call last):
  File "/usr/lib/python3.10/runpy.py", line 196, in _run_module_as_main
    return _run_code(code, main_globals, None,
  File "/usr/lib/python3.10/runpy.py", line 86, in _run_code
    exec(code, run_globals)
  File "/mnt/c/Users/ACER/Documents/service-desk-etl/src/main.py", line 1, in <module>
    from .extract import fetch_source_data
  File "/mnt/c/Users/ACER/Documents/service-desk-etl/src/extract.py", line 1, in <module>
    import requests
ModuleNotFoundError: No module named 'requests'
Traceback (most recent call last):
  File "/usr/lib/python3.10/runpy.py", line 196, in _run_module_as_main
    return _run_code(code, main_globals, None,
  File "/usr/lib/python3.10/runpy.py", line 86, in _run_code
    exec(code, run_globals)
  File "/mnt/c/Users/ACER/Documents/service-desk-etl/src/main.py", line 1, in <module>
    from .extract import fetch_source_data
  File "/mnt/c/Users/ACER/Documents/service-desk-etl/src/extract.py", line 1, in <module>
    import requests
ModuleNotFoundError: No module named 'requests'
Traceback (most recent call last):
  File "/usr/lib/python3.10/runpy.py", line 196, in _run_module_as_main
    return _run_code(code, main_globals, None,
  File "/usr/lib/python3.10/runpy.py", line 86, in _run_code
    exec(code, run_globals)
  File "/mnt/c/Users/ACER/Documents/service-desk-etl/src/main.py", line 1, in <module>
    from .extract import fetch_source_data
  File "/mnt/c/Users/ACER/Documents/service-desk-etl/src/extract.py", line 1, in <module>
    import requests
ModuleNotFoundError: No module named 'requests'
Traceback (most recent call last):
  File "/usr/lib/python3.10/runpy.py", line 196, in _run_module_as_main
    return _run_code(code, main_globals, None,
  File "/usr/lib/python3.10/runpy.py", line 86, in _run_code
    exec(code, run_globals)
  File "/mnt/c/Users/ACER/Documents/service-desk-etl/src/main.py", line 1, in <module>
    from .extract import fetch_source_data
  File "/mnt/c/Users/ACER/Documents/service-desk-etl/src/extract.py", line 1, in <module>
    import requests
ModuleNotFoundError: No module named 'requests'
