2025-10-21 10:23:24,756 | INFO | src.extract | Requesting source API: https://jsonplaceholder.typicode.com/posts
2025-10-21 10:23:25,864 | INFO | src.extract | Fetched 100 records
2025-10-21 10:23:25,910 | INFO | src.transform | dim_user=10, dim_category=1, dim_sla=1, fact_ticket=100
2025-10-21 10:23:25,917 | WARNING | __main__ | Data Quality issues: ['Invalid priority values found in fact_ticket']
2025-10-21 10:23:26,077 | INFO | src.load | Upserted 10 rows into dw.dim_user
2025-10-21 10:23:26,206 | INFO | src.load | Upserted 1 rows into dw.dim_category
2025-10-21 10:23:26,366 | INFO | src.load | Upserted 1 rows into dw.dim_sla
2025-10-21 10:23:26,558 | INFO | src.load | Upserted 100 rows into dw.fact_ticket
2025-10-21 10:30:31,899 | INFO | src.extract | Requesting source API: https://jsonplaceholder.typicode.com/posts
2025-10-21 10:30:32,999 | INFO | src.extract | Fetched 100 records
2025-10-21 10:30:33,048 | INFO | src.transform | dim_user=10, dim_category=1, dim_sla=1, fact_ticket=100
2025-10-21 10:30:33,059 | WARNING | __main__ | Data Quality issues: ['Invalid priority values found in fact_ticket']
2025-10-21 10:30:33,208 | INFO | src.load | Upserted 10 rows into dw.dim_user
2025-10-21 10:30:33,323 | INFO | src.load | Upserted 1 rows into dw.dim_category
2025-10-21 10:30:33,455 | INFO | src.load | Upserted 1 rows into dw.dim_sla
2025-10-21 10:30:33,610 | INFO | src.load | Upserted 100 rows into dw.fact_ticket
2025-10-21 10:35:10,056 | INFO | src.extract | Requesting source API: https://jsonplaceholder.typicode.com/posts
2025-10-21 10:35:11,104 | INFO | src.extract | Fetched 100 records
2025-10-21 10:35:11,156 | INFO | src.transform | dim_user=10, dim_category=1, dim_sla=1, fact_ticket=100
2025-10-21 10:35:11,162 | WARNING | __main__ | Data Quality issues: ['Invalid priority values found in fact_ticket']
2025-10-21 10:35:11,314 | INFO | src.load | Upserted 10 rows into dw.dim_user
2025-10-21 10:35:11,425 | INFO | src.load | Upserted 1 rows into dw.dim_category
2025-10-21 10:35:11,543 | INFO | src.load | Upserted 1 rows into dw.dim_sla
2025-10-21 10:35:11,693 | INFO | src.load | Upserted 100 rows into dw.fact_ticket
2025-10-21 10:40:30,685 | INFO | src.extract | Requesting source API: https://jsonplaceholder.typicode.com/posts
2025-10-21 10:40:31,970 | INFO | src.extract | Fetched 100 records
2025-10-21 10:40:32,033 | INFO | src.transform | dim_user=10, dim_category=1, dim_sla=1, fact_ticket=100
2025-10-21 10:40:32,048 | WARNING | __main__ | Data Quality issues: ['Invalid priority values found in fact_ticket']
2025-10-21 10:40:32,208 | INFO | src.load | Upserted 10 rows into dw.dim_user
2025-10-21 10:40:32,292 | INFO | src.load | Upserted 1 rows into dw.dim_category
2025-10-21 10:40:32,371 | INFO | src.load | Upserted 1 rows into dw.dim_sla
2025-10-21 10:40:32,484 | INFO | src.load | Upserted 100 rows into dw.fact_ticket
2025-10-21 10:47:42,394 | INFO | src.extract | Requesting source API: https://jsonplaceholder.typicode.com/posts
2025-10-21 10:47:43,458 | INFO | src.extract | Fetched 100 records
2025-10-21 10:47:43,499 | INFO | src.transform | dim_user=10, dim_category=1, dim_sla=1, fact_ticket=100
2025-10-21 10:47:43,660 | INFO | src.load | Upserted 10 rows into dw.dim_user
2025-10-21 10:47:43,772 | INFO | src.load | Upserted 1 rows into dw.dim_category
2025-10-21 10:47:43,894 | INFO | src.load | Upserted 1 rows into dw.dim_sla
2025-10-21 10:47:44,028 | INFO | src.load | Upserted 100 rows into dw.fact_ticket
2025-10-21 11:36:35,031 | INFO | __main__ | ===== Starting ETL Run (MANUAL) =====
2025-10-21 11:36:35,171 | INFO | src.extract | Requesting source API: https://jsonplaceholder.typicode.com/posts
2025-10-21 11:36:36,018 | INFO | src.extract | Fetched 100 records
2025-10-21 11:36:36,020 | INFO | __main__ | Fetched 100 raw records
2025-10-21 11:36:36,034 | INFO | src.transform | dim_user=10, dim_category=1, dim_sla=1, fact_ticket=100
2025-10-21 11:36:36,042 | INFO | __main__ | DQ Checks: None
2025-10-21 11:36:36,309 | INFO | src.load | Upserted 10 rows into dw.dim_user
2025-10-21 11:36:36,413 | INFO | src.load | Upserted 1 rows into dw.dim_category
2025-10-21 11:36:36,507 | INFO | src.load | Upserted 1 rows into dw.dim_sla
2025-10-21 11:36:36,698 | INFO | src.load | Upserted 100 rows into dw.fact_ticket
2025-10-21 11:39:50,815 | INFO | __main__ | ===== Starting ETL Run (MANUAL) =====
2025-10-21 11:39:50,920 | INFO | src.extract | Requesting source API: https://jsonplaceholder.typicode.com/posts
2025-10-21 11:39:51,672 | INFO | src.extract | Fetched 100 records
2025-10-21 11:39:51,675 | INFO | __main__ | Fetched 100 raw records
2025-10-21 11:39:51,693 | INFO | src.transform | dim_user=10, dim_category=1, dim_sla=1, fact_ticket=100
2025-10-21 11:39:51,698 | INFO | __main__ | DQ Checks: None
2025-10-21 11:39:51,790 | INFO | src.load | Upserted 10 rows into dw.dim_user
2025-10-21 11:39:51,885 | INFO | src.load | Upserted 1 rows into dw.dim_category
2025-10-21 11:39:51,963 | INFO | src.load | Upserted 1 rows into dw.dim_sla
2025-10-21 11:39:52,075 | INFO | src.load | Upserted 100 rows into dw.fact_ticket
2025-10-21 11:39:52,137 | INFO | __main__ | ETL run complete with status=SUCCESS
2025-10-21 15:00:06,529 | INFO | __main__ | ===== Starting ETL Run ([AUTO-CRON]) =====
2025-10-21 15:00:06,716 | INFO | src.extract | Requesting source API: https://jsonplaceholder.typicode.com/posts
2025-10-21 15:00:07,980 | INFO | src.extract | Fetched 100 records
2025-10-21 15:00:07,985 | INFO | __main__ | Fetched 100 raw records
2025-10-21 15:00:08,030 | INFO | src.transform | dim_user=10, dim_category=1, dim_sla=1, fact_ticket=100
2025-10-21 15:00:08,045 | INFO | __main__ | DQ Checks: None
2025-10-21 15:00:08,260 | INFO | src.load | Upserted 10 rows into dw.dim_user
2025-10-21 15:00:08,349 | INFO | src.load | Upserted 1 rows into dw.dim_category
2025-10-21 15:00:08,421 | INFO | src.load | Upserted 1 rows into dw.dim_sla
2025-10-21 15:00:08,521 | INFO | src.load | Upserted 100 rows into dw.fact_ticket
2025-10-21 15:00:08,570 | INFO | __main__ | ETL run complete with status=SUCCESS
2025-10-22 09:00:15,907 | INFO | __main__ | ===== Starting ETL Run ([AUTO-CRON]) =====
2025-10-22 09:00:16,772 | INFO | src.extract | Requesting source API: https://jsonplaceholder.typicode.com/posts
2025-10-22 09:00:18,552 | INFO | src.extract | Fetched 100 records
2025-10-22 09:00:18,673 | INFO | __main__ | Fetched 100 raw records
2025-10-22 09:00:18,934 | INFO | src.transform | dim_user=10, dim_category=1, dim_sla=1, fact_ticket=100
2025-10-22 09:00:19,008 | INFO | __main__ | DQ Checks: None
2025-10-22 09:00:19,554 | ERROR | __main__ | ETL Failed
Traceback (most recent call last):
  File "/home/root123/.local/lib/python3.12/site-packages/sqlalchemy/engine/base.py", line 143, in __init__
    self._dbapi_connection = engine.raw_connection()
                             ^^^^^^^^^^^^^^^^^^^^^^^
  File "/home/root123/.local/lib/python3.12/site-packages/sqlalchemy/engine/base.py", line 3301, in raw_connection
    return self.pool.connect()
           ^^^^^^^^^^^^^^^^^^^
  File "/home/root123/.local/lib/python3.12/site-packages/sqlalchemy/pool/base.py", line 447, in connect
    return _ConnectionFairy._checkout(self)
           ^^^^^^^^^^^^^^^^^^^^^^^^^^^^^^^^
  File "/home/root123/.local/lib/python3.12/site-packages/sqlalchemy/pool/base.py", line 1264, in _checkout
    fairy = _ConnectionRecord.checkout(pool)
            ^^^^^^^^^^^^^^^^^^^^^^^^^^^^^^^^
  File "/home/root123/.local/lib/python3.12/site-packages/sqlalchemy/pool/base.py", line 711, in checkout
    rec = pool._do_get()
          ^^^^^^^^^^^^^^
  File "/home/root123/.local/lib/python3.12/site-packages/sqlalchemy/pool/impl.py", line 177, in _do_get
    with util.safe_reraise():
  File "/home/root123/.local/lib/python3.12/site-packages/sqlalchemy/util/langhelpers.py", line 224, in __exit__
    raise exc_value.with_traceback(exc_tb)
  File "/home/root123/.local/lib/python3.12/site-packages/sqlalchemy/pool/impl.py", line 175, in _do_get
    return self._create_connection()
           ^^^^^^^^^^^^^^^^^^^^^^^^^
  File "/home/root123/.local/lib/python3.12/site-packages/sqlalchemy/pool/base.py", line 388, in _create_connection
    return _ConnectionRecord(self)
           ^^^^^^^^^^^^^^^^^^^^^^^
  File "/home/root123/.local/lib/python3.12/site-packages/sqlalchemy/pool/base.py", line 673, in __init__
    self.__connect()
  File "/home/root123/.local/lib/python3.12/site-packages/sqlalchemy/pool/base.py", line 899, in __connect
    with util.safe_reraise():
  File "/home/root123/.local/lib/python3.12/site-packages/sqlalchemy/util/langhelpers.py", line 224, in __exit__
    raise exc_value.with_traceback(exc_tb)
  File "/home/root123/.local/lib/python3.12/site-packages/sqlalchemy/pool/base.py", line 895, in __connect
    self.dbapi_connection = connection = pool._invoke_creator(self)
                                         ^^^^^^^^^^^^^^^^^^^^^^^^^^
  File "/home/root123/.local/lib/python3.12/site-packages/sqlalchemy/engine/create.py", line 661, in connect
    return dialect.connect(*cargs, **cparams)
           ^^^^^^^^^^^^^^^^^^^^^^^^^^^^^^^^^^
  File "/home/root123/.local/lib/python3.12/site-packages/sqlalchemy/engine/default.py", line 629, in connect
    return self.loaded_dbapi.connect(*cargs, **cparams)  # type: ignore[no-any-return]  # NOQA: E501
           ^^^^^^^^^^^^^^^^^^^^^^^^^^^^^^^^^^^^^^^^^^^^
  File "/home/root123/.local/lib/python3.12/site-packages/psycopg2/__init__.py", line 122, in connect
    conn = _connect(dsn, connection_factory=connection_factory, **kwasync)
           ^^^^^^^^^^^^^^^^^^^^^^^^^^^^^^^^^^^^^^^^^^^^^^^^^^^^^^^^^^^^^^^
psycopg2.OperationalError: connection to server at "localhost" (127.0.0.1), port 5432 failed: Connection refused
	Is the server running on that host and accepting TCP/IP connections?


The above exception was the direct cause of the following exception:

Traceback (most recent call last):
  File "/mnt/c/Users/ACER/Documents/service-desk-etl/src/main.py", line 44, in run
    upsert_frame(tables["dim_user"], "dim_user", ["user_id"])
  File "/mnt/c/Users/ACER/Documents/service-desk-etl/src/load.py", line 14, in upsert_frame
    with engine.begin() as conn:
  File "/usr/lib/python3.12/contextlib.py", line 137, in __enter__
    return next(self.gen)
           ^^^^^^^^^^^^^^
  File "/home/root123/.local/lib/python3.12/site-packages/sqlalchemy/engine/base.py", line 3241, in begin
    with self.connect() as conn:
         ^^^^^^^^^^^^^^
  File "/home/root123/.local/lib/python3.12/site-packages/sqlalchemy/engine/base.py", line 3277, in connect
    return self._connection_cls(self)
           ^^^^^^^^^^^^^^^^^^^^^^^^^^
  File "/home/root123/.local/lib/python3.12/site-packages/sqlalchemy/engine/base.py", line 145, in __init__
    Connection._handle_dbapi_exception_noconnection(
  File "/home/root123/.local/lib/python3.12/site-packages/sqlalchemy/engine/base.py", line 2440, in _handle_dbapi_exception_noconnection
    raise sqlalchemy_exception.with_traceback(exc_info[2]) from e
  File "/home/root123/.local/lib/python3.12/site-packages/sqlalchemy/engine/base.py", line 143, in __init__
    self._dbapi_connection = engine.raw_connection()
                             ^^^^^^^^^^^^^^^^^^^^^^^
  File "/home/root123/.local/lib/python3.12/site-packages/sqlalchemy/engine/base.py", line 3301, in raw_connection
    return self.pool.connect()
           ^^^^^^^^^^^^^^^^^^^
  File "/home/root123/.local/lib/python3.12/site-packages/sqlalchemy/pool/base.py", line 447, in connect
    return _ConnectionFairy._checkout(self)
           ^^^^^^^^^^^^^^^^^^^^^^^^^^^^^^^^
  File "/home/root123/.local/lib/python3.12/site-packages/sqlalchemy/pool/base.py", line 1264, in _checkout
    fairy = _ConnectionRecord.checkout(pool)
            ^^^^^^^^^^^^^^^^^^^^^^^^^^^^^^^^
  File "/home/root123/.local/lib/python3.12/site-packages/sqlalchemy/pool/base.py", line 711, in checkout
    rec = pool._do_get()
          ^^^^^^^^^^^^^^
  File "/home/root123/.local/lib/python3.12/site-packages/sqlalchemy/pool/impl.py", line 177, in _do_get
    with util.safe_reraise():
  File "/home/root123/.local/lib/python3.12/site-packages/sqlalchemy/util/langhelpers.py", line 224, in __exit__
    raise exc_value.with_traceback(exc_tb)
  File "/home/root123/.local/lib/python3.12/site-packages/sqlalchemy/pool/impl.py", line 175, in _do_get
    return self._create_connection()
           ^^^^^^^^^^^^^^^^^^^^^^^^^
  File "/home/root123/.local/lib/python3.12/site-packages/sqlalchemy/pool/base.py", line 388, in _create_connection
    return _ConnectionRecord(self)
           ^^^^^^^^^^^^^^^^^^^^^^^
  File "/home/root123/.local/lib/python3.12/site-packages/sqlalchemy/pool/base.py", line 673, in __init__
    self.__connect()
  File "/home/root123/.local/lib/python3.12/site-packages/sqlalchemy/pool/base.py", line 899, in __connect
    with util.safe_reraise():
  File "/home/root123/.local/lib/python3.12/site-packages/sqlalchemy/util/langhelpers.py", line 224, in __exit__
    raise exc_value.with_traceback(exc_tb)
  File "/home/root123/.local/lib/python3.12/site-packages/sqlalchemy/pool/base.py", line 895, in __connect
    self.dbapi_connection = connection = pool._invoke_creator(self)
                                         ^^^^^^^^^^^^^^^^^^^^^^^^^^
  File "/home/root123/.local/lib/python3.12/site-packages/sqlalchemy/engine/create.py", line 661, in connect
    return dialect.connect(*cargs, **cparams)
           ^^^^^^^^^^^^^^^^^^^^^^^^^^^^^^^^^^
  File "/home/root123/.local/lib/python3.12/site-packages/sqlalchemy/engine/default.py", line 629, in connect
    return self.loaded_dbapi.connect(*cargs, **cparams)  # type: ignore[no-any-return]  # NOQA: E501
           ^^^^^^^^^^^^^^^^^^^^^^^^^^^^^^^^^^^^^^^^^^^^
  File "/home/root123/.local/lib/python3.12/site-packages/psycopg2/__init__.py", line 122, in connect
    conn = _connect(dsn, connection_factory=connection_factory, **kwasync)
           ^^^^^^^^^^^^^^^^^^^^^^^^^^^^^^^^^^^^^^^^^^^^^^^^^^^^^^^^^^^^^^^
sqlalchemy.exc.OperationalError: (psycopg2.OperationalError) connection to server at "localhost" (127.0.0.1), port 5432 failed: Connection refused
	Is the server running on that host and accepting TCP/IP connections?

(Background on this error at: https://sqlalche.me/e/20/e3q8)
2025-10-22 09:00:55,199 | INFO | __main__ | ===== Starting ETL Run (MANUAL) =====
2025-10-22 09:01:00,228 | INFO | src.extract | Requesting source API: https://jsonplaceholder.typicode.com/posts
2025-10-22 09:01:00,957 | INFO | src.extract | Fetched 100 records
2025-10-22 09:01:01,011 | INFO | __main__ | Fetched 100 raw records
2025-10-22 09:01:01,094 | INFO | src.transform | dim_user=10, dim_category=1, dim_sla=1, fact_ticket=100
2025-10-22 09:01:01,110 | INFO | __main__ | DQ Checks: None
2025-10-22 09:01:05,230 | ERROR | __main__ | ETL Failed
Traceback (most recent call last):
  File "C:\Users\ACER\Documents\service-desk-etl\venv\lib\site-packages\sqlalchemy\engine\base.py", line 3371, in _wrap_pool_connect
    return fn()
  File "C:\Users\ACER\Documents\service-desk-etl\venv\lib\site-packages\sqlalchemy\pool\base.py", line 327, in connect
    return _ConnectionFairy._checkout(self)
  File "C:\Users\ACER\Documents\service-desk-etl\venv\lib\site-packages\sqlalchemy\pool\base.py", line 894, in _checkout
    fairy = _ConnectionRecord.checkout(pool)
  File "C:\Users\ACER\Documents\service-desk-etl\venv\lib\site-packages\sqlalchemy\pool\base.py", line 493, in checkout
    rec = pool._do_get()
  File "C:\Users\ACER\Documents\service-desk-etl\venv\lib\site-packages\sqlalchemy\pool\impl.py", line 145, in _do_get
    with util.safe_reraise():
  File "C:\Users\ACER\Documents\service-desk-etl\venv\lib\site-packages\sqlalchemy\util\langhelpers.py", line 70, in __exit__
    compat.raise_(
  File "C:\Users\ACER\Documents\service-desk-etl\venv\lib\site-packages\sqlalchemy\util\compat.py", line 211, in raise_
    raise exception
  File "C:\Users\ACER\Documents\service-desk-etl\venv\lib\site-packages\sqlalchemy\pool\impl.py", line 143, in _do_get
    return self._create_connection()
  File "C:\Users\ACER\Documents\service-desk-etl\venv\lib\site-packages\sqlalchemy\pool\base.py", line 273, in _create_connection
    return _ConnectionRecord(self)
  File "C:\Users\ACER\Documents\service-desk-etl\venv\lib\site-packages\sqlalchemy\pool\base.py", line 388, in __init__
    self.__connect()
  File "C:\Users\ACER\Documents\service-desk-etl\venv\lib\site-packages\sqlalchemy\pool\base.py", line 690, in __connect
    with util.safe_reraise():
  File "C:\Users\ACER\Documents\service-desk-etl\venv\lib\site-packages\sqlalchemy\util\langhelpers.py", line 70, in __exit__
    compat.raise_(
  File "C:\Users\ACER\Documents\service-desk-etl\venv\lib\site-packages\sqlalchemy\util\compat.py", line 211, in raise_
    raise exception
  File "C:\Users\ACER\Documents\service-desk-etl\venv\lib\site-packages\sqlalchemy\pool\base.py", line 686, in __connect
    self.dbapi_connection = connection = pool._invoke_creator(self)
  File "C:\Users\ACER\Documents\service-desk-etl\venv\lib\site-packages\sqlalchemy\engine\create.py", line 574, in connect
    return dialect.connect(*cargs, **cparams)
  File "C:\Users\ACER\Documents\service-desk-etl\venv\lib\site-packages\sqlalchemy\engine\default.py", line 598, in connect
    return self.dbapi.connect(*cargs, **cparams)
  File "C:\Users\ACER\Documents\service-desk-etl\venv\lib\site-packages\psycopg2\__init__.py", line 135, in connect
    conn = _connect(dsn, connection_factory=connection_factory, **kwasync)
psycopg2.OperationalError: connection to server at "localhost" (::1), port 5432 failed: Connection refused (0x0000274D/10061)
	Is the server running on that host and accepting TCP/IP connections?
connection to server at "localhost" (127.0.0.1), port 5432 failed: Connection refused (0x0000274D/10061)
	Is the server running on that host and accepting TCP/IP connections?


The above exception was the direct cause of the following exception:

Traceback (most recent call last):
  File "C:\Users\ACER\Documents\service-desk-etl\src\main.py", line 44, in run
    upsert_frame(tables["dim_user"], "dim_user", ["user_id"])
  File "C:\Users\ACER\Documents\service-desk-etl\src\load.py", line 14, in upsert_frame
    with engine.begin() as conn:
  File "C:\Users\ACER\AppData\Local\Programs\Python\Python310\lib\contextlib.py", line 135, in __enter__
    return next(self.gen)
  File "C:\Users\ACER\Documents\service-desk-etl\venv\lib\site-packages\sqlalchemy\future\engine.py", line 385, in begin
    with self.connect() as conn:
  File "C:\Users\ACER\Documents\service-desk-etl\venv\lib\site-packages\sqlalchemy\future\engine.py", line 412, in connect
    return super(Engine, self).connect()
  File "C:\Users\ACER\Documents\service-desk-etl\venv\lib\site-packages\sqlalchemy\engine\base.py", line 3325, in connect
    return self._connection_cls(self, close_with_result=close_with_result)
  File "C:\Users\ACER\Documents\service-desk-etl\venv\lib\site-packages\sqlalchemy\engine\base.py", line 96, in __init__
    else engine.raw_connection()
  File "C:\Users\ACER\Documents\service-desk-etl\venv\lib\site-packages\sqlalchemy\engine\base.py", line 3404, in raw_connection
    return self._wrap_pool_connect(self.pool.connect, _connection)
  File "C:\Users\ACER\Documents\service-desk-etl\venv\lib\site-packages\sqlalchemy\engine\base.py", line 3374, in _wrap_pool_connect
    Connection._handle_dbapi_exception_noconnection(
  File "C:\Users\ACER\Documents\service-desk-etl\venv\lib\site-packages\sqlalchemy\engine\base.py", line 2208, in _handle_dbapi_exception_noconnection
    util.raise_(
  File "C:\Users\ACER\Documents\service-desk-etl\venv\lib\site-packages\sqlalchemy\util\compat.py", line 211, in raise_
    raise exception
  File "C:\Users\ACER\Documents\service-desk-etl\venv\lib\site-packages\sqlalchemy\engine\base.py", line 3371, in _wrap_pool_connect
    return fn()
  File "C:\Users\ACER\Documents\service-desk-etl\venv\lib\site-packages\sqlalchemy\pool\base.py", line 327, in connect
    return _ConnectionFairy._checkout(self)
  File "C:\Users\ACER\Documents\service-desk-etl\venv\lib\site-packages\sqlalchemy\pool\base.py", line 894, in _checkout
    fairy = _ConnectionRecord.checkout(pool)
  File "C:\Users\ACER\Documents\service-desk-etl\venv\lib\site-packages\sqlalchemy\pool\base.py", line 493, in checkout
    rec = pool._do_get()
  File "C:\Users\ACER\Documents\service-desk-etl\venv\lib\site-packages\sqlalchemy\pool\impl.py", line 145, in _do_get
    with util.safe_reraise():
  File "C:\Users\ACER\Documents\service-desk-etl\venv\lib\site-packages\sqlalchemy\util\langhelpers.py", line 70, in __exit__
    compat.raise_(
  File "C:\Users\ACER\Documents\service-desk-etl\venv\lib\site-packages\sqlalchemy\util\compat.py", line 211, in raise_
    raise exception
  File "C:\Users\ACER\Documents\service-desk-etl\venv\lib\site-packages\sqlalchemy\pool\impl.py", line 143, in _do_get
    return self._create_connection()
  File "C:\Users\ACER\Documents\service-desk-etl\venv\lib\site-packages\sqlalchemy\pool\base.py", line 273, in _create_connection
    return _ConnectionRecord(self)
  File "C:\Users\ACER\Documents\service-desk-etl\venv\lib\site-packages\sqlalchemy\pool\base.py", line 388, in __init__
    self.__connect()
  File "C:\Users\ACER\Documents\service-desk-etl\venv\lib\site-packages\sqlalchemy\pool\base.py", line 690, in __connect
    with util.safe_reraise():
  File "C:\Users\ACER\Documents\service-desk-etl\venv\lib\site-packages\sqlalchemy\util\langhelpers.py", line 70, in __exit__
    compat.raise_(
  File "C:\Users\ACER\Documents\service-desk-etl\venv\lib\site-packages\sqlalchemy\util\compat.py", line 211, in raise_
    raise exception
  File "C:\Users\ACER\Documents\service-desk-etl\venv\lib\site-packages\sqlalchemy\pool\base.py", line 686, in __connect
    self.dbapi_connection = connection = pool._invoke_creator(self)
  File "C:\Users\ACER\Documents\service-desk-etl\venv\lib\site-packages\sqlalchemy\engine\create.py", line 574, in connect
    return dialect.connect(*cargs, **cparams)
  File "C:\Users\ACER\Documents\service-desk-etl\venv\lib\site-packages\sqlalchemy\engine\default.py", line 598, in connect
    return self.dbapi.connect(*cargs, **cparams)
  File "C:\Users\ACER\Documents\service-desk-etl\venv\lib\site-packages\psycopg2\__init__.py", line 135, in connect
    conn = _connect(dsn, connection_factory=connection_factory, **kwasync)
sqlalchemy.exc.OperationalError: (psycopg2.OperationalError) connection to server at "localhost" (::1), port 5432 failed: Connection refused (0x0000274D/10061)
	Is the server running on that host and accepting TCP/IP connections?
connection to server at "localhost" (127.0.0.1), port 5432 failed: Connection refused (0x0000274D/10061)
	Is the server running on that host and accepting TCP/IP connections?

(Background on this error at: https://sqlalche.me/e/14/e3q8)
2025-10-22 10:06:49,438 | INFO | __main__ | ===== Starting ETL Run (MANUAL) =====
2025-10-22 10:06:49,720 | INFO | src.extract | Requesting source API: https://jsonplaceholder.typicode.com/posts
2025-10-22 10:06:50,113 | INFO | src.extract | Fetched 100 records
2025-10-22 10:06:50,113 | INFO | __main__ | Fetched 100 raw records
2025-10-22 10:06:50,174 | INFO | src.transform | dim_user=10, dim_category=1, dim_sla=1, fact_ticket=100
2025-10-22 10:06:50,183 | INFO | __main__ | DQ Checks: None
2025-10-22 10:06:54,298 | ERROR | __main__ | ETL Failed
Traceback (most recent call last):
  File "C:\Users\ACER\Documents\service-desk-etl\venv\lib\site-packages\sqlalchemy\engine\base.py", line 3371, in _wrap_pool_connect
    return fn()
  File "C:\Users\ACER\Documents\service-desk-etl\venv\lib\site-packages\sqlalchemy\pool\base.py", line 327, in connect
    return _ConnectionFairy._checkout(self)
  File "C:\Users\ACER\Documents\service-desk-etl\venv\lib\site-packages\sqlalchemy\pool\base.py", line 894, in _checkout
    fairy = _ConnectionRecord.checkout(pool)
  File "C:\Users\ACER\Documents\service-desk-etl\venv\lib\site-packages\sqlalchemy\pool\base.py", line 493, in checkout
    rec = pool._do_get()
  File "C:\Users\ACER\Documents\service-desk-etl\venv\lib\site-packages\sqlalchemy\pool\impl.py", line 145, in _do_get
    with util.safe_reraise():
  File "C:\Users\ACER\Documents\service-desk-etl\venv\lib\site-packages\sqlalchemy\util\langhelpers.py", line 70, in __exit__
    compat.raise_(
  File "C:\Users\ACER\Documents\service-desk-etl\venv\lib\site-packages\sqlalchemy\util\compat.py", line 211, in raise_
    raise exception
  File "C:\Users\ACER\Documents\service-desk-etl\venv\lib\site-packages\sqlalchemy\pool\impl.py", line 143, in _do_get
    return self._create_connection()
  File "C:\Users\ACER\Documents\service-desk-etl\venv\lib\site-packages\sqlalchemy\pool\base.py", line 273, in _create_connection
    return _ConnectionRecord(self)
  File "C:\Users\ACER\Documents\service-desk-etl\venv\lib\site-packages\sqlalchemy\pool\base.py", line 388, in __init__
    self.__connect()
  File "C:\Users\ACER\Documents\service-desk-etl\venv\lib\site-packages\sqlalchemy\pool\base.py", line 690, in __connect
    with util.safe_reraise():
  File "C:\Users\ACER\Documents\service-desk-etl\venv\lib\site-packages\sqlalchemy\util\langhelpers.py", line 70, in __exit__
    compat.raise_(
  File "C:\Users\ACER\Documents\service-desk-etl\venv\lib\site-packages\sqlalchemy\util\compat.py", line 211, in raise_
    raise exception
  File "C:\Users\ACER\Documents\service-desk-etl\venv\lib\site-packages\sqlalchemy\pool\base.py", line 686, in __connect
    self.dbapi_connection = connection = pool._invoke_creator(self)
  File "C:\Users\ACER\Documents\service-desk-etl\venv\lib\site-packages\sqlalchemy\engine\create.py", line 574, in connect
    return dialect.connect(*cargs, **cparams)
  File "C:\Users\ACER\Documents\service-desk-etl\venv\lib\site-packages\sqlalchemy\engine\default.py", line 598, in connect
    return self.dbapi.connect(*cargs, **cparams)
  File "C:\Users\ACER\Documents\service-desk-etl\venv\lib\site-packages\psycopg2\__init__.py", line 135, in connect
    conn = _connect(dsn, connection_factory=connection_factory, **kwasync)
psycopg2.OperationalError: connection to server at "localhost" (::1), port 5432 failed: Connection refused (0x0000274D/10061)
	Is the server running on that host and accepting TCP/IP connections?
connection to server at "localhost" (127.0.0.1), port 5432 failed: Connection refused (0x0000274D/10061)
	Is the server running on that host and accepting TCP/IP connections?


The above exception was the direct cause of the following exception:

Traceback (most recent call last):
  File "C:\Users\ACER\Documents\service-desk-etl\src\main.py", line 44, in run
    upsert_frame(tables["dim_user"], "dim_user", ["user_id"])
  File "C:\Users\ACER\Documents\service-desk-etl\src\load.py", line 14, in upsert_frame
    with engine.begin() as conn:
  File "C:\Users\ACER\AppData\Local\Programs\Python\Python310\lib\contextlib.py", line 135, in __enter__
    return next(self.gen)
  File "C:\Users\ACER\Documents\service-desk-etl\venv\lib\site-packages\sqlalchemy\future\engine.py", line 385, in begin
    with self.connect() as conn:
  File "C:\Users\ACER\Documents\service-desk-etl\venv\lib\site-packages\sqlalchemy\future\engine.py", line 412, in connect
    return super(Engine, self).connect()
  File "C:\Users\ACER\Documents\service-desk-etl\venv\lib\site-packages\sqlalchemy\engine\base.py", line 3325, in connect
    return self._connection_cls(self, close_with_result=close_with_result)
  File "C:\Users\ACER\Documents\service-desk-etl\venv\lib\site-packages\sqlalchemy\engine\base.py", line 96, in __init__
    else engine.raw_connection()
  File "C:\Users\ACER\Documents\service-desk-etl\venv\lib\site-packages\sqlalchemy\engine\base.py", line 3404, in raw_connection
    return self._wrap_pool_connect(self.pool.connect, _connection)
  File "C:\Users\ACER\Documents\service-desk-etl\venv\lib\site-packages\sqlalchemy\engine\base.py", line 3374, in _wrap_pool_connect
    Connection._handle_dbapi_exception_noconnection(
  File "C:\Users\ACER\Documents\service-desk-etl\venv\lib\site-packages\sqlalchemy\engine\base.py", line 2208, in _handle_dbapi_exception_noconnection
    util.raise_(
  File "C:\Users\ACER\Documents\service-desk-etl\venv\lib\site-packages\sqlalchemy\util\compat.py", line 211, in raise_
    raise exception
  File "C:\Users\ACER\Documents\service-desk-etl\venv\lib\site-packages\sqlalchemy\engine\base.py", line 3371, in _wrap_pool_connect
    return fn()
  File "C:\Users\ACER\Documents\service-desk-etl\venv\lib\site-packages\sqlalchemy\pool\base.py", line 327, in connect
    return _ConnectionFairy._checkout(self)
  File "C:\Users\ACER\Documents\service-desk-etl\venv\lib\site-packages\sqlalchemy\pool\base.py", line 894, in _checkout
    fairy = _ConnectionRecord.checkout(pool)
  File "C:\Users\ACER\Documents\service-desk-etl\venv\lib\site-packages\sqlalchemy\pool\base.py", line 493, in checkout
    rec = pool._do_get()
  File "C:\Users\ACER\Documents\service-desk-etl\venv\lib\site-packages\sqlalchemy\pool\impl.py", line 145, in _do_get
    with util.safe_reraise():
  File "C:\Users\ACER\Documents\service-desk-etl\venv\lib\site-packages\sqlalchemy\util\langhelpers.py", line 70, in __exit__
    compat.raise_(
  File "C:\Users\ACER\Documents\service-desk-etl\venv\lib\site-packages\sqlalchemy\util\compat.py", line 211, in raise_
    raise exception
  File "C:\Users\ACER\Documents\service-desk-etl\venv\lib\site-packages\sqlalchemy\pool\impl.py", line 143, in _do_get
    return self._create_connection()
  File "C:\Users\ACER\Documents\service-desk-etl\venv\lib\site-packages\sqlalchemy\pool\base.py", line 273, in _create_connection
    return _ConnectionRecord(self)
  File "C:\Users\ACER\Documents\service-desk-etl\venv\lib\site-packages\sqlalchemy\pool\base.py", line 388, in __init__
    self.__connect()
  File "C:\Users\ACER\Documents\service-desk-etl\venv\lib\site-packages\sqlalchemy\pool\base.py", line 690, in __connect
    with util.safe_reraise():
  File "C:\Users\ACER\Documents\service-desk-etl\venv\lib\site-packages\sqlalchemy\util\langhelpers.py", line 70, in __exit__
    compat.raise_(
  File "C:\Users\ACER\Documents\service-desk-etl\venv\lib\site-packages\sqlalchemy\util\compat.py", line 211, in raise_
    raise exception
  File "C:\Users\ACER\Documents\service-desk-etl\venv\lib\site-packages\sqlalchemy\pool\base.py", line 686, in __connect
    self.dbapi_connection = connection = pool._invoke_creator(self)
  File "C:\Users\ACER\Documents\service-desk-etl\venv\lib\site-packages\sqlalchemy\engine\create.py", line 574, in connect
    return dialect.connect(*cargs, **cparams)
  File "C:\Users\ACER\Documents\service-desk-etl\venv\lib\site-packages\sqlalchemy\engine\default.py", line 598, in connect
    return self.dbapi.connect(*cargs, **cparams)
  File "C:\Users\ACER\Documents\service-desk-etl\venv\lib\site-packages\psycopg2\__init__.py", line 135, in connect
    conn = _connect(dsn, connection_factory=connection_factory, **kwasync)
sqlalchemy.exc.OperationalError: (psycopg2.OperationalError) connection to server at "localhost" (::1), port 5432 failed: Connection refused (0x0000274D/10061)
	Is the server running on that host and accepting TCP/IP connections?
connection to server at "localhost" (127.0.0.1), port 5432 failed: Connection refused (0x0000274D/10061)
	Is the server running on that host and accepting TCP/IP connections?

(Background on this error at: https://sqlalche.me/e/14/e3q8)
2025-10-22 10:09:42,982 | INFO | __main__ | ===== Starting ETL Run (MANUAL) =====
2025-10-22 10:09:43,116 | INFO | src.extract | Requesting source API: https://jsonplaceholder.typicode.com/posts
2025-10-22 10:09:43,625 | INFO | src.extract | Fetched 100 records
2025-10-22 10:09:43,627 | INFO | __main__ | Fetched 100 raw records
2025-10-22 10:09:43,680 | INFO | src.transform | dim_user=10, dim_category=1, dim_sla=1, fact_ticket=100
2025-10-22 10:09:43,689 | INFO | __main__ | DQ Checks: None
2025-10-22 10:09:47,782 | ERROR | __main__ | ETL Failed
Traceback (most recent call last):
  File "C:\Users\ACER\Documents\service-desk-etl\venv\lib\site-packages\sqlalchemy\engine\base.py", line 3371, in _wrap_pool_connect
    return fn()
  File "C:\Users\ACER\Documents\service-desk-etl\venv\lib\site-packages\sqlalchemy\pool\base.py", line 327, in connect
    return _ConnectionFairy._checkout(self)
  File "C:\Users\ACER\Documents\service-desk-etl\venv\lib\site-packages\sqlalchemy\pool\base.py", line 894, in _checkout
    fairy = _ConnectionRecord.checkout(pool)
  File "C:\Users\ACER\Documents\service-desk-etl\venv\lib\site-packages\sqlalchemy\pool\base.py", line 493, in checkout
    rec = pool._do_get()
  File "C:\Users\ACER\Documents\service-desk-etl\venv\lib\site-packages\sqlalchemy\pool\impl.py", line 145, in _do_get
    with util.safe_reraise():
  File "C:\Users\ACER\Documents\service-desk-etl\venv\lib\site-packages\sqlalchemy\util\langhelpers.py", line 70, in __exit__
    compat.raise_(
  File "C:\Users\ACER\Documents\service-desk-etl\venv\lib\site-packages\sqlalchemy\util\compat.py", line 211, in raise_
    raise exception
  File "C:\Users\ACER\Documents\service-desk-etl\venv\lib\site-packages\sqlalchemy\pool\impl.py", line 143, in _do_get
    return self._create_connection()
  File "C:\Users\ACER\Documents\service-desk-etl\venv\lib\site-packages\sqlalchemy\pool\base.py", line 273, in _create_connection
    return _ConnectionRecord(self)
  File "C:\Users\ACER\Documents\service-desk-etl\venv\lib\site-packages\sqlalchemy\pool\base.py", line 388, in __init__
    self.__connect()
  File "C:\Users\ACER\Documents\service-desk-etl\venv\lib\site-packages\sqlalchemy\pool\base.py", line 690, in __connect
    with util.safe_reraise():
  File "C:\Users\ACER\Documents\service-desk-etl\venv\lib\site-packages\sqlalchemy\util\langhelpers.py", line 70, in __exit__
    compat.raise_(
  File "C:\Users\ACER\Documents\service-desk-etl\venv\lib\site-packages\sqlalchemy\util\compat.py", line 211, in raise_
    raise exception
  File "C:\Users\ACER\Documents\service-desk-etl\venv\lib\site-packages\sqlalchemy\pool\base.py", line 686, in __connect
    self.dbapi_connection = connection = pool._invoke_creator(self)
  File "C:\Users\ACER\Documents\service-desk-etl\venv\lib\site-packages\sqlalchemy\engine\create.py", line 574, in connect
    return dialect.connect(*cargs, **cparams)
  File "C:\Users\ACER\Documents\service-desk-etl\venv\lib\site-packages\sqlalchemy\engine\default.py", line 598, in connect
    return self.dbapi.connect(*cargs, **cparams)
  File "C:\Users\ACER\Documents\service-desk-etl\venv\lib\site-packages\psycopg2\__init__.py", line 135, in connect
    conn = _connect(dsn, connection_factory=connection_factory, **kwasync)
psycopg2.OperationalError: connection to server at "localhost" (::1), port 5432 failed: Connection refused (0x0000274D/10061)
	Is the server running on that host and accepting TCP/IP connections?
connection to server at "localhost" (127.0.0.1), port 5432 failed: Connection refused (0x0000274D/10061)
	Is the server running on that host and accepting TCP/IP connections?


The above exception was the direct cause of the following exception:

Traceback (most recent call last):
  File "C:\Users\ACER\Documents\service-desk-etl\src\main.py", line 44, in run
    upsert_frame(tables["dim_user"], "dim_user", ["user_id"])
  File "C:\Users\ACER\Documents\service-desk-etl\src\load.py", line 14, in upsert_frame
    with engine.begin() as conn:
  File "C:\Users\ACER\AppData\Local\Programs\Python\Python310\lib\contextlib.py", line 135, in __enter__
    return next(self.gen)
  File "C:\Users\ACER\Documents\service-desk-etl\venv\lib\site-packages\sqlalchemy\future\engine.py", line 385, in begin
    with self.connect() as conn:
  File "C:\Users\ACER\Documents\service-desk-etl\venv\lib\site-packages\sqlalchemy\future\engine.py", line 412, in connect
    return super(Engine, self).connect()
  File "C:\Users\ACER\Documents\service-desk-etl\venv\lib\site-packages\sqlalchemy\engine\base.py", line 3325, in connect
    return self._connection_cls(self, close_with_result=close_with_result)
  File "C:\Users\ACER\Documents\service-desk-etl\venv\lib\site-packages\sqlalchemy\engine\base.py", line 96, in __init__
    else engine.raw_connection()
  File "C:\Users\ACER\Documents\service-desk-etl\venv\lib\site-packages\sqlalchemy\engine\base.py", line 3404, in raw_connection
    return self._wrap_pool_connect(self.pool.connect, _connection)
  File "C:\Users\ACER\Documents\service-desk-etl\venv\lib\site-packages\sqlalchemy\engine\base.py", line 3374, in _wrap_pool_connect
    Connection._handle_dbapi_exception_noconnection(
  File "C:\Users\ACER\Documents\service-desk-etl\venv\lib\site-packages\sqlalchemy\engine\base.py", line 2208, in _handle_dbapi_exception_noconnection
    util.raise_(
  File "C:\Users\ACER\Documents\service-desk-etl\venv\lib\site-packages\sqlalchemy\util\compat.py", line 211, in raise_
    raise exception
  File "C:\Users\ACER\Documents\service-desk-etl\venv\lib\site-packages\sqlalchemy\engine\base.py", line 3371, in _wrap_pool_connect
    return fn()
  File "C:\Users\ACER\Documents\service-desk-etl\venv\lib\site-packages\sqlalchemy\pool\base.py", line 327, in connect
    return _ConnectionFairy._checkout(self)
  File "C:\Users\ACER\Documents\service-desk-etl\venv\lib\site-packages\sqlalchemy\pool\base.py", line 894, in _checkout
    fairy = _ConnectionRecord.checkout(pool)
  File "C:\Users\ACER\Documents\service-desk-etl\venv\lib\site-packages\sqlalchemy\pool\base.py", line 493, in checkout
    rec = pool._do_get()
  File "C:\Users\ACER\Documents\service-desk-etl\venv\lib\site-packages\sqlalchemy\pool\impl.py", line 145, in _do_get
    with util.safe_reraise():
  File "C:\Users\ACER\Documents\service-desk-etl\venv\lib\site-packages\sqlalchemy\util\langhelpers.py", line 70, in __exit__
    compat.raise_(
  File "C:\Users\ACER\Documents\service-desk-etl\venv\lib\site-packages\sqlalchemy\util\compat.py", line 211, in raise_
    raise exception
  File "C:\Users\ACER\Documents\service-desk-etl\venv\lib\site-packages\sqlalchemy\pool\impl.py", line 143, in _do_get
    return self._create_connection()
  File "C:\Users\ACER\Documents\service-desk-etl\venv\lib\site-packages\sqlalchemy\pool\base.py", line 273, in _create_connection
    return _ConnectionRecord(self)
  File "C:\Users\ACER\Documents\service-desk-etl\venv\lib\site-packages\sqlalchemy\pool\base.py", line 388, in __init__
    self.__connect()
  File "C:\Users\ACER\Documents\service-desk-etl\venv\lib\site-packages\sqlalchemy\pool\base.py", line 690, in __connect
    with util.safe_reraise():
  File "C:\Users\ACER\Documents\service-desk-etl\venv\lib\site-packages\sqlalchemy\util\langhelpers.py", line 70, in __exit__
    compat.raise_(
  File "C:\Users\ACER\Documents\service-desk-etl\venv\lib\site-packages\sqlalchemy\util\compat.py", line 211, in raise_
    raise exception
  File "C:\Users\ACER\Documents\service-desk-etl\venv\lib\site-packages\sqlalchemy\pool\base.py", line 686, in __connect
    self.dbapi_connection = connection = pool._invoke_creator(self)
  File "C:\Users\ACER\Documents\service-desk-etl\venv\lib\site-packages\sqlalchemy\engine\create.py", line 574, in connect
    return dialect.connect(*cargs, **cparams)
  File "C:\Users\ACER\Documents\service-desk-etl\venv\lib\site-packages\sqlalchemy\engine\default.py", line 598, in connect
    return self.dbapi.connect(*cargs, **cparams)
  File "C:\Users\ACER\Documents\service-desk-etl\venv\lib\site-packages\psycopg2\__init__.py", line 135, in connect
    conn = _connect(dsn, connection_factory=connection_factory, **kwasync)
sqlalchemy.exc.OperationalError: (psycopg2.OperationalError) connection to server at "localhost" (::1), port 5432 failed: Connection refused (0x0000274D/10061)
	Is the server running on that host and accepting TCP/IP connections?
connection to server at "localhost" (127.0.0.1), port 5432 failed: Connection refused (0x0000274D/10061)
	Is the server running on that host and accepting TCP/IP connections?

(Background on this error at: https://sqlalche.me/e/14/e3q8)
2025-10-22 10:11:07,702 | INFO | __main__ | ===== Starting ETL Run (MANUAL) =====
2025-10-22 10:11:07,824 | INFO | src.extract | Requesting source API: https://jsonplaceholder.typicode.com/posts
2025-10-22 10:11:08,109 | INFO | src.extract | Fetched 100 records
2025-10-22 10:11:08,113 | INFO | __main__ | Fetched 100 raw records
2025-10-22 10:11:08,134 | INFO | src.transform | dim_user=10, dim_category=1, dim_sla=1, fact_ticket=100
2025-10-22 10:11:08,143 | INFO | __main__ | DQ Checks: None
2025-10-22 10:11:08,615 | ERROR | __main__ | ETL Failed
Traceback (most recent call last):
  File "C:\Users\ACER\Documents\service-desk-etl\src\main.py", line 44, in run
    upsert_frame(tables["dim_user"], "dim_user", ["user_id"])
  File "C:\Users\ACER\Documents\service-desk-etl\src\load.py", line 18, in upsert_frame
    df.head(0).to_sql(tmp.split('.')[-1], conn, schema="dw", if_exists="replace", index=False)
  File "C:\Users\ACER\Documents\service-desk-etl\venv\lib\site-packages\pandas\util\_decorators.py", line 333, in wrapper
    return func(*args, **kwargs)
  File "C:\Users\ACER\Documents\service-desk-etl\venv\lib\site-packages\pandas\core\generic.py", line 3109, in to_sql
    return sql.to_sql(
  File "C:\Users\ACER\Documents\service-desk-etl\venv\lib\site-packages\pandas\io\sql.py", line 844, in to_sql
    return pandas_sql.to_sql(
  File "C:\Users\ACER\Documents\service-desk-etl\venv\lib\site-packages\pandas\io\sql.py", line 2840, in to_sql
    table.create()
  File "C:\Users\ACER\Documents\service-desk-etl\venv\lib\site-packages\pandas\io\sql.py", line 986, in create
    if self.exists():
  File "C:\Users\ACER\Documents\service-desk-etl\venv\lib\site-packages\pandas\io\sql.py", line 972, in exists
    return self.pd_sql.has_table(self.name, self.schema)
  File "C:\Users\ACER\Documents\service-desk-etl\venv\lib\site-packages\pandas\io\sql.py", line 2855, in has_table
    return len(self.execute(query, [name]).fetchall()) > 0
  File "C:\Users\ACER\Documents\service-desk-etl\venv\lib\site-packages\pandas\io\sql.py", line 2662, in execute
    cur = self.con.cursor()
AttributeError: 'Connection' object has no attribute 'cursor'
2025-10-22 10:11:08,690 | INFO | __main__ | ETL run complete with status=FAILED
2025-10-22 11:08:34,091 | INFO | __main__ | ===== Starting ETL Run (MANUAL) =====
2025-10-22 11:08:37,420 | INFO | src.extract | Requesting source API: https://jsonplaceholder.typicode.com/posts
2025-10-22 11:08:38,603 | INFO | src.extract | Fetched 100 records
2025-10-22 11:08:38,607 | INFO | __main__ | Fetched 100 raw records
2025-10-22 11:08:38,630 | INFO | src.transform | dim_user=10, dim_category=1, dim_sla=1, fact_ticket=100
2025-10-22 11:08:38,636 | INFO | __main__ | DQ Checks: None
2025-10-22 11:08:39,059 | INFO | src.load | Upserted 10 rows into dw.dim_user
2025-10-22 11:08:39,152 | INFO | src.load | Upserted 1 rows into dw.dim_category
2025-10-22 11:08:39,244 | INFO | src.load | Upserted 1 rows into dw.dim_sla
2025-10-22 11:08:39,383 | INFO | src.load | Upserted 100 rows into dw.fact_ticket
2025-10-22 11:08:39,437 | INFO | __main__ | ETL run complete with status=SUCCESS
2025-10-22 14:56:57,519 | INFO | __main__ | ===== Starting ETL Run (MANUAL) =====
2025-10-22 14:57:00,428 | INFO | src.extract | Requesting source API: https://jsonplaceholder.typicode.com/posts
2025-10-22 14:57:00,980 | INFO | src.extract | Fetched 100 records
2025-10-22 14:57:00,986 | INFO | __main__ | Fetched 100 raw records
2025-10-22 14:57:01,013 | INFO | src.transform | dim_user=10, dim_category=1, dim_sla=1, fact_ticket=100
2025-10-22 14:57:01,023 | INFO | __main__ | DQ Checks: None
2025-10-22 14:57:01,465 | INFO | src.load | Upserted 10 rows into dw.dim_user
2025-10-22 14:57:01,586 | INFO | src.load | Upserted 1 rows into dw.dim_category
2025-10-22 14:57:01,706 | INFO | src.load | Upserted 1 rows into dw.dim_sla
2025-10-22 14:57:01,854 | INFO | src.load | Upserted 100 rows into dw.fact_ticket
2025-10-22 14:57:01,923 | INFO | __main__ | ETL run complete with status=SUCCESS
